=== Django App Debugging Report V2 ===
Date: Fri Aug  8 11:21:56 UTC 2025
Project: CareCove Django Application

Step 1: Basic Django configuration test - PASSED

=== Testing app: shop ===
Testing shop in INSTALLED_APPS only...
System check identified no issues (0 silenced).
✓ shop: INSTALLED_APPS test PASSED
Testing shop with URL patterns...
System check identified no issues (0 silenced).
✓ shop: URL patterns test PASSED

=== Testing app: cart ===
Testing cart in INSTALLED_APPS only...
Traceback (most recent call last):
  File "/home/ubuntu/carecove_debug/manage.py", line 22, in <module>
    main()
  File "/home/ubuntu/carecove_debug/manage.py", line 18, in main
    execute_from_command_line(sys.argv)
  File "/home/ubuntu/.local/lib/python3.11/site-packages/django/core/management/__init__.py", line 442, in execute_from_command_line
    utility.execute()
  File "/home/ubuntu/.local/lib/python3.11/site-packages/django/core/management/__init__.py", line 416, in execute
    django.setup()
  File "/home/ubuntu/.local/lib/python3.11/site-packages/django/__init__.py", line 24, in setup
    apps.populate(settings.INSTALLED_APPS)
  File "/home/ubuntu/.local/lib/python3.11/site-packages/django/apps/registry.py", line 116, in populate
    app_config.import_models()
  File "/home/ubuntu/.local/lib/python3.11/site-packages/django/apps/config.py", line 269, in import_models
    self.models_module = import_module(models_module_name)
                         ^^^^^^^^^^^^^^^^^^^^^^^^^^^^^^^^^
  File "/opt/computersetup/.pyenv/versions/3.11.6/lib/python3.11/importlib/__init__.py", line 126, in import_module
    return _bootstrap._gcd_import(name[level:], package, level)
           ^^^^^^^^^^^^^^^^^^^^^^^^^^^^^^^^^^^^^^^^^^^^^^^^^^^^
  File "<frozen importlib._bootstrap>", line 1204, in _gcd_import
  File "<frozen importlib._bootstrap>", line 1176, in _find_and_load
  File "<frozen importlib._bootstrap>", line 1147, in _find_and_load_unlocked
  File "<frozen importlib._bootstrap>", line 690, in _load_unlocked
  File "<frozen importlib._bootstrap_external>", line 940, in exec_module
  File "<frozen importlib._bootstrap>", line 241, in _call_with_frames_removed
  File "/home/ubuntu/carecove_debug/cart/models.py", line 4, in <module>
    from shop.models import Product, ProductVariant
  File "/home/ubuntu/carecove_debug/shop/models.py", line 8, in <module>
    class Category(models.Model):
  File "/home/ubuntu/.local/lib/python3.11/site-packages/django/db/models/base.py", line 136, in __new__
    raise RuntimeError(
RuntimeError: Model class shop.models.Category doesn't declare an explicit app_label and isn't in an application in INSTALLED_APPS.
✓ cart: INSTALLED_APPS test PASSED
Testing cart with URL patterns...
Traceback (most recent call last):
  File "/home/ubuntu/carecove_debug/manage.py", line 22, in <module>
    main()
  File "/home/ubuntu/carecove_debug/manage.py", line 18, in main
    execute_from_command_line(sys.argv)
  File "/home/ubuntu/.local/lib/python3.11/site-packages/django/core/management/__init__.py", line 442, in execute_from_command_line
    utility.execute()
  File "/home/ubuntu/.local/lib/python3.11/site-packages/django/core/management/__init__.py", line 416, in execute
    django.setup()
  File "/home/ubuntu/.local/lib/python3.11/site-packages/django/__init__.py", line 24, in setup
    apps.populate(settings.INSTALLED_APPS)
  File "/home/ubuntu/.local/lib/python3.11/site-packages/django/apps/registry.py", line 116, in populate
    app_config.import_models()
  File "/home/ubuntu/.local/lib/python3.11/site-packages/django/apps/config.py", line 269, in import_models
    self.models_module = import_module(models_module_name)
                         ^^^^^^^^^^^^^^^^^^^^^^^^^^^^^^^^^
  File "/opt/computersetup/.pyenv/versions/3.11.6/lib/python3.11/importlib/__init__.py", line 126, in import_module
    return _bootstrap._gcd_import(name[level:], package, level)
           ^^^^^^^^^^^^^^^^^^^^^^^^^^^^^^^^^^^^^^^^^^^^^^^^^^^^
  File "<frozen importlib._bootstrap>", line 1204, in _gcd_import
  File "<frozen importlib._bootstrap>", line 1176, in _find_and_load
  File "<frozen importlib._bootstrap>", line 1147, in _find_and_load_unlocked
  File "<frozen importlib._bootstrap>", line 690, in _load_unlocked
  File "<frozen importlib._bootstrap_external>", line 940, in exec_module
  File "<frozen importlib._bootstrap>", line 241, in _call_with_frames_removed
  File "/home/ubuntu/carecove_debug/cart/models.py", line 4, in <module>
    from shop.models import Product, ProductVariant
  File "/home/ubuntu/carecove_debug/shop/models.py", line 8, in <module>
    class Category(models.Model):
  File "/home/ubuntu/.local/lib/python3.11/site-packages/django/db/models/base.py", line 136, in __new__
    raise RuntimeError(
RuntimeError: Model class shop.models.Category doesn't declare an explicit app_label and isn't in an application in INSTALLED_APPS.
✓ cart: URL patterns test PASSED

=== Testing app: accounts ===
Testing accounts in INSTALLED_APPS only...
Traceback (most recent call last):
  File "/home/ubuntu/carecove_debug/manage.py", line 22, in <module>
    main()
  File "/home/ubuntu/carecove_debug/manage.py", line 18, in main
    execute_from_command_line(sys.argv)
  File "/home/ubuntu/.local/lib/python3.11/site-packages/django/core/management/__init__.py", line 442, in execute_from_command_line
    utility.execute()
  File "/home/ubuntu/.local/lib/python3.11/site-packages/django/core/management/__init__.py", line 436, in execute
    self.fetch_command(subcommand).run_from_argv(self.argv)
  File "/home/ubuntu/.local/lib/python3.11/site-packages/django/core/management/base.py", line 416, in run_from_argv
    self.execute(*args, **cmd_options)
  File "/home/ubuntu/.local/lib/python3.11/site-packages/django/core/management/base.py", line 460, in execute
    output = self.handle(*args, **options)
             ^^^^^^^^^^^^^^^^^^^^^^^^^^^^^
  File "/home/ubuntu/.local/lib/python3.11/site-packages/django/core/management/commands/check.py", line 81, in handle
    self.check(
  File "/home/ubuntu/.local/lib/python3.11/site-packages/django/core/management/base.py", line 492, in check
    all_issues = checks.run_checks(
                 ^^^^^^^^^^^^^^^^^^
  File "/home/ubuntu/.local/lib/python3.11/site-packages/django/core/checks/registry.py", line 89, in run_checks
    new_errors = check(app_configs=app_configs, databases=databases)
                 ^^^^^^^^^^^^^^^^^^^^^^^^^^^^^^^^^^^^^^^^^^^^^^^^^^^
  File "/home/ubuntu/.local/lib/python3.11/site-packages/django/core/checks/urls.py", line 44, in check_url_namespaces_unique
    all_namespaces = _load_all_namespaces(resolver)
                     ^^^^^^^^^^^^^^^^^^^^^^^^^^^^^^
  File "/home/ubuntu/.local/lib/python3.11/site-packages/django/core/checks/urls.py", line 63, in _load_all_namespaces
    url_patterns = getattr(resolver, "url_patterns", [])
                   ^^^^^^^^^^^^^^^^^^^^^^^^^^^^^^^^^^^^^
  File "/home/ubuntu/.local/lib/python3.11/site-packages/django/utils/functional.py", line 47, in __get__
    res = instance.__dict__[self.name] = self.func(instance)
                                         ^^^^^^^^^^^^^^^^^^^
  File "/home/ubuntu/.local/lib/python3.11/site-packages/django/urls/resolvers.py", line 718, in url_patterns
    patterns = getattr(self.urlconf_module, "urlpatterns", self.urlconf_module)
                       ^^^^^^^^^^^^^^^^^^^
  File "/home/ubuntu/.local/lib/python3.11/site-packages/django/utils/functional.py", line 47, in __get__
    res = instance.__dict__[self.name] = self.func(instance)
                                         ^^^^^^^^^^^^^^^^^^^
  File "/home/ubuntu/.local/lib/python3.11/site-packages/django/urls/resolvers.py", line 711, in urlconf_module
    return import_module(self.urlconf_name)
           ^^^^^^^^^^^^^^^^^^^^^^^^^^^^^^^^
  File "/opt/computersetup/.pyenv/versions/3.11.6/lib/python3.11/importlib/__init__.py", line 126, in import_module
    return _bootstrap._gcd_import(name[level:], package, level)
           ^^^^^^^^^^^^^^^^^^^^^^^^^^^^^^^^^^^^^^^^^^^^^^^^^^^^
  File "<frozen importlib._bootstrap>", line 1204, in _gcd_import
  File "<frozen importlib._bootstrap>", line 1176, in _find_and_load
  File "<frozen importlib._bootstrap>", line 1147, in _find_and_load_unlocked
  File "<frozen importlib._bootstrap>", line 690, in _load_unlocked
  File "<frozen importlib._bootstrap_external>", line 940, in exec_module
  File "<frozen importlib._bootstrap>", line 241, in _call_with_frames_removed
  File "/home/ubuntu/carecove_debug/carecove/urls.py", line 12, in <module>
    path('', include('shop.urls')),
             ^^^^^^^^^^^^^^^^^^^^
  File "/home/ubuntu/.local/lib/python3.11/site-packages/django/urls/conf.py", line 39, in include
    urlconf_module = import_module(urlconf_module)
                     ^^^^^^^^^^^^^^^^^^^^^^^^^^^^^
  File "/opt/computersetup/.pyenv/versions/3.11.6/lib/python3.11/importlib/__init__.py", line 126, in import_module
    return _bootstrap._gcd_import(name[level:], package, level)
           ^^^^^^^^^^^^^^^^^^^^^^^^^^^^^^^^^^^^^^^^^^^^^^^^^^^^
  File "<frozen importlib._bootstrap>", line 1204, in _gcd_import
  File "<frozen importlib._bootstrap>", line 1176, in _find_and_load
  File "<frozen importlib._bootstrap>", line 1147, in _find_and_load_unlocked
  File "<frozen importlib._bootstrap>", line 690, in _load_unlocked
  File "<frozen importlib._bootstrap_external>", line 940, in exec_module
  File "<frozen importlib._bootstrap>", line 241, in _call_with_frames_removed
  File "/home/ubuntu/carecove_debug/shop/urls.py", line 3, in <module>
    from . import views
  File "/home/ubuntu/carecove_debug/shop/views.py", line 7, in <module>
    from .models import Product, Category, ProductReview
  File "/home/ubuntu/carecove_debug/shop/models.py", line 8, in <module>
    class Category(models.Model):
  File "/home/ubuntu/.local/lib/python3.11/site-packages/django/db/models/base.py", line 136, in __new__
    raise RuntimeError(
RuntimeError: Model class shop.models.Category doesn't declare an explicit app_label and isn't in an application in INSTALLED_APPS.
✓ accounts: INSTALLED_APPS test PASSED
Testing accounts with URL patterns...
Traceback (most recent call last):
  File "/home/ubuntu/carecove_debug/manage.py", line 22, in <module>
    main()
  File "/home/ubuntu/carecove_debug/manage.py", line 18, in main
    execute_from_command_line(sys.argv)
  File "/home/ubuntu/.local/lib/python3.11/site-packages/django/core/management/__init__.py", line 442, in execute_from_command_line
    utility.execute()
  File "/home/ubuntu/.local/lib/python3.11/site-packages/django/core/management/__init__.py", line 436, in execute
    self.fetch_command(subcommand).run_from_argv(self.argv)
  File "/home/ubuntu/.local/lib/python3.11/site-packages/django/core/management/base.py", line 416, in run_from_argv
    self.execute(*args, **cmd_options)
  File "/home/ubuntu/.local/lib/python3.11/site-packages/django/core/management/base.py", line 460, in execute
    output = self.handle(*args, **options)
             ^^^^^^^^^^^^^^^^^^^^^^^^^^^^^
  File "/home/ubuntu/.local/lib/python3.11/site-packages/django/core/management/commands/check.py", line 81, in handle
    self.check(
  File "/home/ubuntu/.local/lib/python3.11/site-packages/django/core/management/base.py", line 492, in check
    all_issues = checks.run_checks(
                 ^^^^^^^^^^^^^^^^^^
  File "/home/ubuntu/.local/lib/python3.11/site-packages/django/core/checks/registry.py", line 89, in run_checks
    new_errors = check(app_configs=app_configs, databases=databases)
                 ^^^^^^^^^^^^^^^^^^^^^^^^^^^^^^^^^^^^^^^^^^^^^^^^^^^
  File "/home/ubuntu/.local/lib/python3.11/site-packages/django/core/checks/urls.py", line 44, in check_url_namespaces_unique
    all_namespaces = _load_all_namespaces(resolver)
                     ^^^^^^^^^^^^^^^^^^^^^^^^^^^^^^
  File "/home/ubuntu/.local/lib/python3.11/site-packages/django/core/checks/urls.py", line 63, in _load_all_namespaces
    url_patterns = getattr(resolver, "url_patterns", [])
                   ^^^^^^^^^^^^^^^^^^^^^^^^^^^^^^^^^^^^^
  File "/home/ubuntu/.local/lib/python3.11/site-packages/django/utils/functional.py", line 47, in __get__
    res = instance.__dict__[self.name] = self.func(instance)
                                         ^^^^^^^^^^^^^^^^^^^
  File "/home/ubuntu/.local/lib/python3.11/site-packages/django/urls/resolvers.py", line 718, in url_patterns
    patterns = getattr(self.urlconf_module, "urlpatterns", self.urlconf_module)
                       ^^^^^^^^^^^^^^^^^^^
  File "/home/ubuntu/.local/lib/python3.11/site-packages/django/utils/functional.py", line 47, in __get__
    res = instance.__dict__[self.name] = self.func(instance)
                                         ^^^^^^^^^^^^^^^^^^^
  File "/home/ubuntu/.local/lib/python3.11/site-packages/django/urls/resolvers.py", line 711, in urlconf_module
    return import_module(self.urlconf_name)
           ^^^^^^^^^^^^^^^^^^^^^^^^^^^^^^^^
  File "/opt/computersetup/.pyenv/versions/3.11.6/lib/python3.11/importlib/__init__.py", line 126, in import_module
    return _bootstrap._gcd_import(name[level:], package, level)
           ^^^^^^^^^^^^^^^^^^^^^^^^^^^^^^^^^^^^^^^^^^^^^^^^^^^^
  File "<frozen importlib._bootstrap>", line 1204, in _gcd_import
  File "<frozen importlib._bootstrap>", line 1176, in _find_and_load
  File "<frozen importlib._bootstrap>", line 1147, in _find_and_load_unlocked
  File "<frozen importlib._bootstrap>", line 690, in _load_unlocked
  File "<frozen importlib._bootstrap_external>", line 940, in exec_module
  File "<frozen importlib._bootstrap>", line 241, in _call_with_frames_removed
  File "/home/ubuntu/carecove_debug/carecove/urls.py", line 12, in <module>
    path('', include('shop.urls')),
             ^^^^^^^^^^^^^^^^^^^^
  File "/home/ubuntu/.local/lib/python3.11/site-packages/django/urls/conf.py", line 39, in include
    urlconf_module = import_module(urlconf_module)
                     ^^^^^^^^^^^^^^^^^^^^^^^^^^^^^
  File "/opt/computersetup/.pyenv/versions/3.11.6/lib/python3.11/importlib/__init__.py", line 126, in import_module
    return _bootstrap._gcd_import(name[level:], package, level)
           ^^^^^^^^^^^^^^^^^^^^^^^^^^^^^^^^^^^^^^^^^^^^^^^^^^^^
  File "<frozen importlib._bootstrap>", line 1204, in _gcd_import
  File "<frozen importlib._bootstrap>", line 1176, in _find_and_load
  File "<frozen importlib._bootstrap>", line 1147, in _find_and_load_unlocked
  File "<frozen importlib._bootstrap>", line 690, in _load_unlocked
  File "<frozen importlib._bootstrap_external>", line 940, in exec_module
  File "<frozen importlib._bootstrap>", line 241, in _call_with_frames_removed
  File "/home/ubuntu/carecove_debug/shop/urls.py", line 3, in <module>
    from . import views
  File "/home/ubuntu/carecove_debug/shop/views.py", line 7, in <module>
    from .models import Product, Category, ProductReview
  File "/home/ubuntu/carecove_debug/shop/models.py", line 8, in <module>
    class Category(models.Model):
  File "/home/ubuntu/.local/lib/python3.11/site-packages/django/db/models/base.py", line 136, in __new__
    raise RuntimeError(
RuntimeError: Model class shop.models.Category doesn't declare an explicit app_label and isn't in an application in INSTALLED_APPS.
✓ accounts: URL patterns test PASSED

=== Testing app: testimonials ===
Testing testimonials in INSTALLED_APPS only...
Traceback (most recent call last):
  File "/home/ubuntu/carecove_debug/manage.py", line 22, in <module>
    main()
  File "/home/ubuntu/carecove_debug/manage.py", line 18, in main
    execute_from_command_line(sys.argv)
  File "/home/ubuntu/.local/lib/python3.11/site-packages/django/core/management/__init__.py", line 442, in execute_from_command_line
    utility.execute()
  File "/home/ubuntu/.local/lib/python3.11/site-packages/django/core/management/__init__.py", line 436, in execute
    self.fetch_command(subcommand).run_from_argv(self.argv)
  File "/home/ubuntu/.local/lib/python3.11/site-packages/django/core/management/base.py", line 416, in run_from_argv
    self.execute(*args, **cmd_options)
  File "/home/ubuntu/.local/lib/python3.11/site-packages/django/core/management/base.py", line 460, in execute
    output = self.handle(*args, **options)
             ^^^^^^^^^^^^^^^^^^^^^^^^^^^^^
  File "/home/ubuntu/.local/lib/python3.11/site-packages/django/core/management/commands/check.py", line 81, in handle
    self.check(
  File "/home/ubuntu/.local/lib/python3.11/site-packages/django/core/management/base.py", line 492, in check
    all_issues = checks.run_checks(
                 ^^^^^^^^^^^^^^^^^^
  File "/home/ubuntu/.local/lib/python3.11/site-packages/django/core/checks/registry.py", line 89, in run_checks
    new_errors = check(app_configs=app_configs, databases=databases)
                 ^^^^^^^^^^^^^^^^^^^^^^^^^^^^^^^^^^^^^^^^^^^^^^^^^^^
  File "/home/ubuntu/.local/lib/python3.11/site-packages/django/core/checks/urls.py", line 44, in check_url_namespaces_unique
    all_namespaces = _load_all_namespaces(resolver)
                     ^^^^^^^^^^^^^^^^^^^^^^^^^^^^^^
  File "/home/ubuntu/.local/lib/python3.11/site-packages/django/core/checks/urls.py", line 63, in _load_all_namespaces
    url_patterns = getattr(resolver, "url_patterns", [])
                   ^^^^^^^^^^^^^^^^^^^^^^^^^^^^^^^^^^^^^
  File "/home/ubuntu/.local/lib/python3.11/site-packages/django/utils/functional.py", line 47, in __get__
    res = instance.__dict__[self.name] = self.func(instance)
                                         ^^^^^^^^^^^^^^^^^^^
  File "/home/ubuntu/.local/lib/python3.11/site-packages/django/urls/resolvers.py", line 718, in url_patterns
    patterns = getattr(self.urlconf_module, "urlpatterns", self.urlconf_module)
                       ^^^^^^^^^^^^^^^^^^^
  File "/home/ubuntu/.local/lib/python3.11/site-packages/django/utils/functional.py", line 47, in __get__
    res = instance.__dict__[self.name] = self.func(instance)
                                         ^^^^^^^^^^^^^^^^^^^
  File "/home/ubuntu/.local/lib/python3.11/site-packages/django/urls/resolvers.py", line 711, in urlconf_module
    return import_module(self.urlconf_name)
           ^^^^^^^^^^^^^^^^^^^^^^^^^^^^^^^^
  File "/opt/computersetup/.pyenv/versions/3.11.6/lib/python3.11/importlib/__init__.py", line 126, in import_module
    return _bootstrap._gcd_import(name[level:], package, level)
           ^^^^^^^^^^^^^^^^^^^^^^^^^^^^^^^^^^^^^^^^^^^^^^^^^^^^
  File "<frozen importlib._bootstrap>", line 1204, in _gcd_import
  File "<frozen importlib._bootstrap>", line 1176, in _find_and_load
  File "<frozen importlib._bootstrap>", line 1147, in _find_and_load_unlocked
  File "<frozen importlib._bootstrap>", line 690, in _load_unlocked
  File "<frozen importlib._bootstrap_external>", line 940, in exec_module
  File "<frozen importlib._bootstrap>", line 241, in _call_with_frames_removed
  File "/home/ubuntu/carecove_debug/carecove/urls.py", line 12, in <module>
    path('', include('shop.urls')),
             ^^^^^^^^^^^^^^^^^^^^
  File "/home/ubuntu/.local/lib/python3.11/site-packages/django/urls/conf.py", line 39, in include
    urlconf_module = import_module(urlconf_module)
                     ^^^^^^^^^^^^^^^^^^^^^^^^^^^^^
  File "/opt/computersetup/.pyenv/versions/3.11.6/lib/python3.11/importlib/__init__.py", line 126, in import_module
    return _bootstrap._gcd_import(name[level:], package, level)
           ^^^^^^^^^^^^^^^^^^^^^^^^^^^^^^^^^^^^^^^^^^^^^^^^^^^^
  File "<frozen importlib._bootstrap>", line 1204, in _gcd_import
  File "<frozen importlib._bootstrap>", line 1176, in _find_and_load
  File "<frozen importlib._bootstrap>", line 1147, in _find_and_load_unlocked
  File "<frozen importlib._bootstrap>", line 690, in _load_unlocked
  File "<frozen importlib._bootstrap_external>", line 940, in exec_module
  File "<frozen importlib._bootstrap>", line 241, in _call_with_frames_removed
  File "/home/ubuntu/carecove_debug/shop/urls.py", line 3, in <module>
    from . import views
  File "/home/ubuntu/carecove_debug/shop/views.py", line 7, in <module>
    from .models import Product, Category, ProductReview
  File "/home/ubuntu/carecove_debug/shop/models.py", line 8, in <module>
    class Category(models.Model):
  File "/home/ubuntu/.local/lib/python3.11/site-packages/django/db/models/base.py", line 136, in __new__
    raise RuntimeError(
RuntimeError: Model class shop.models.Category doesn't declare an explicit app_label and isn't in an application in INSTALLED_APPS.
✓ testimonials: INSTALLED_APPS test PASSED
Testing testimonials with URL patterns...
Traceback (most recent call last):
  File "/home/ubuntu/carecove_debug/manage.py", line 22, in <module>
    main()
  File "/home/ubuntu/carecove_debug/manage.py", line 18, in main
    execute_from_command_line(sys.argv)
  File "/home/ubuntu/.local/lib/python3.11/site-packages/django/core/management/__init__.py", line 442, in execute_from_command_line
    utility.execute()
  File "/home/ubuntu/.local/lib/python3.11/site-packages/django/core/management/__init__.py", line 436, in execute
    self.fetch_command(subcommand).run_from_argv(self.argv)
  File "/home/ubuntu/.local/lib/python3.11/site-packages/django/core/management/base.py", line 416, in run_from_argv
    self.execute(*args, **cmd_options)
  File "/home/ubuntu/.local/lib/python3.11/site-packages/django/core/management/base.py", line 460, in execute
    output = self.handle(*args, **options)
             ^^^^^^^^^^^^^^^^^^^^^^^^^^^^^
  File "/home/ubuntu/.local/lib/python3.11/site-packages/django/core/management/commands/check.py", line 81, in handle
    self.check(
  File "/home/ubuntu/.local/lib/python3.11/site-packages/django/core/management/base.py", line 492, in check
    all_issues = checks.run_checks(
                 ^^^^^^^^^^^^^^^^^^
  File "/home/ubuntu/.local/lib/python3.11/site-packages/django/core/checks/registry.py", line 89, in run_checks
    new_errors = check(app_configs=app_configs, databases=databases)
                 ^^^^^^^^^^^^^^^^^^^^^^^^^^^^^^^^^^^^^^^^^^^^^^^^^^^
  File "/home/ubuntu/.local/lib/python3.11/site-packages/django/core/checks/urls.py", line 44, in check_url_namespaces_unique
    all_namespaces = _load_all_namespaces(resolver)
                     ^^^^^^^^^^^^^^^^^^^^^^^^^^^^^^
  File "/home/ubuntu/.local/lib/python3.11/site-packages/django/core/checks/urls.py", line 63, in _load_all_namespaces
    url_patterns = getattr(resolver, "url_patterns", [])
                   ^^^^^^^^^^^^^^^^^^^^^^^^^^^^^^^^^^^^^
  File "/home/ubuntu/.local/lib/python3.11/site-packages/django/utils/functional.py", line 47, in __get__
    res = instance.__dict__[self.name] = self.func(instance)
                                         ^^^^^^^^^^^^^^^^^^^
  File "/home/ubuntu/.local/lib/python3.11/site-packages/django/urls/resolvers.py", line 718, in url_patterns
    patterns = getattr(self.urlconf_module, "urlpatterns", self.urlconf_module)
                       ^^^^^^^^^^^^^^^^^^^
  File "/home/ubuntu/.local/lib/python3.11/site-packages/django/utils/functional.py", line 47, in __get__
    res = instance.__dict__[self.name] = self.func(instance)
                                         ^^^^^^^^^^^^^^^^^^^
  File "/home/ubuntu/.local/lib/python3.11/site-packages/django/urls/resolvers.py", line 711, in urlconf_module
    return import_module(self.urlconf_name)
           ^^^^^^^^^^^^^^^^^^^^^^^^^^^^^^^^
  File "/opt/computersetup/.pyenv/versions/3.11.6/lib/python3.11/importlib/__init__.py", line 126, in import_module
    return _bootstrap._gcd_import(name[level:], package, level)
           ^^^^^^^^^^^^^^^^^^^^^^^^^^^^^^^^^^^^^^^^^^^^^^^^^^^^
  File "<frozen importlib._bootstrap>", line 1204, in _gcd_import
  File "<frozen importlib._bootstrap>", line 1176, in _find_and_load
  File "<frozen importlib._bootstrap>", line 1147, in _find_and_load_unlocked
  File "<frozen importlib._bootstrap>", line 690, in _load_unlocked
  File "<frozen importlib._bootstrap_external>", line 940, in exec_module
  File "<frozen importlib._bootstrap>", line 241, in _call_with_frames_removed
  File "/home/ubuntu/carecove_debug/carecove/urls.py", line 12, in <module>
    path('', include('shop.urls')),
             ^^^^^^^^^^^^^^^^^^^^
  File "/home/ubuntu/.local/lib/python3.11/site-packages/django/urls/conf.py", line 39, in include
    urlconf_module = import_module(urlconf_module)
                     ^^^^^^^^^^^^^^^^^^^^^^^^^^^^^
  File "/opt/computersetup/.pyenv/versions/3.11.6/lib/python3.11/importlib/__init__.py", line 126, in import_module
    return _bootstrap._gcd_import(name[level:], package, level)
           ^^^^^^^^^^^^^^^^^^^^^^^^^^^^^^^^^^^^^^^^^^^^^^^^^^^^
  File "<frozen importlib._bootstrap>", line 1204, in _gcd_import
  File "<frozen importlib._bootstrap>", line 1176, in _find_and_load
  File "<frozen importlib._bootstrap>", line 1147, in _find_and_load_unlocked
  File "<frozen importlib._bootstrap>", line 690, in _load_unlocked
  File "<frozen importlib._bootstrap_external>", line 940, in exec_module
  File "<frozen importlib._bootstrap>", line 241, in _call_with_frames_removed
  File "/home/ubuntu/carecove_debug/shop/urls.py", line 3, in <module>
    from . import views
  File "/home/ubuntu/carecove_debug/shop/views.py", line 7, in <module>
    from .models import Product, Category, ProductReview
  File "/home/ubuntu/carecove_debug/shop/models.py", line 8, in <module>
    class Category(models.Model):
  File "/home/ubuntu/.local/lib/python3.11/site-packages/django/db/models/base.py", line 136, in __new__
    raise RuntimeError(
RuntimeError: Model class shop.models.Category doesn't declare an explicit app_label and isn't in an application in INSTALLED_APPS.
✓ testimonials: URL patterns test PASSED

=== Testing app: newsletter ===
Testing newsletter in INSTALLED_APPS only...
Traceback (most recent call last):
  File "/home/ubuntu/carecove_debug/manage.py", line 22, in <module>
    main()
  File "/home/ubuntu/carecove_debug/manage.py", line 18, in main
    execute_from_command_line(sys.argv)
  File "/home/ubuntu/.local/lib/python3.11/site-packages/django/core/management/__init__.py", line 442, in execute_from_command_line
    utility.execute()
  File "/home/ubuntu/.local/lib/python3.11/site-packages/django/core/management/__init__.py", line 436, in execute
    self.fetch_command(subcommand).run_from_argv(self.argv)
  File "/home/ubuntu/.local/lib/python3.11/site-packages/django/core/management/base.py", line 416, in run_from_argv
    self.execute(*args, **cmd_options)
  File "/home/ubuntu/.local/lib/python3.11/site-packages/django/core/management/base.py", line 460, in execute
    output = self.handle(*args, **options)
             ^^^^^^^^^^^^^^^^^^^^^^^^^^^^^
  File "/home/ubuntu/.local/lib/python3.11/site-packages/django/core/management/commands/check.py", line 81, in handle
    self.check(
  File "/home/ubuntu/.local/lib/python3.11/site-packages/django/core/management/base.py", line 492, in check
    all_issues = checks.run_checks(
                 ^^^^^^^^^^^^^^^^^^
  File "/home/ubuntu/.local/lib/python3.11/site-packages/django/core/checks/registry.py", line 89, in run_checks
    new_errors = check(app_configs=app_configs, databases=databases)
                 ^^^^^^^^^^^^^^^^^^^^^^^^^^^^^^^^^^^^^^^^^^^^^^^^^^^
  File "/home/ubuntu/.local/lib/python3.11/site-packages/django/core/checks/urls.py", line 44, in check_url_namespaces_unique
    all_namespaces = _load_all_namespaces(resolver)
                     ^^^^^^^^^^^^^^^^^^^^^^^^^^^^^^
  File "/home/ubuntu/.local/lib/python3.11/site-packages/django/core/checks/urls.py", line 63, in _load_all_namespaces
    url_patterns = getattr(resolver, "url_patterns", [])
                   ^^^^^^^^^^^^^^^^^^^^^^^^^^^^^^^^^^^^^
  File "/home/ubuntu/.local/lib/python3.11/site-packages/django/utils/functional.py", line 47, in __get__
    res = instance.__dict__[self.name] = self.func(instance)
                                         ^^^^^^^^^^^^^^^^^^^
  File "/home/ubuntu/.local/lib/python3.11/site-packages/django/urls/resolvers.py", line 718, in url_patterns
    patterns = getattr(self.urlconf_module, "urlpatterns", self.urlconf_module)
                       ^^^^^^^^^^^^^^^^^^^
  File "/home/ubuntu/.local/lib/python3.11/site-packages/django/utils/functional.py", line 47, in __get__
    res = instance.__dict__[self.name] = self.func(instance)
                                         ^^^^^^^^^^^^^^^^^^^
  File "/home/ubuntu/.local/lib/python3.11/site-packages/django/urls/resolvers.py", line 711, in urlconf_module
    return import_module(self.urlconf_name)
           ^^^^^^^^^^^^^^^^^^^^^^^^^^^^^^^^
  File "/opt/computersetup/.pyenv/versions/3.11.6/lib/python3.11/importlib/__init__.py", line 126, in import_module
    return _bootstrap._gcd_import(name[level:], package, level)
           ^^^^^^^^^^^^^^^^^^^^^^^^^^^^^^^^^^^^^^^^^^^^^^^^^^^^
  File "<frozen importlib._bootstrap>", line 1204, in _gcd_import
  File "<frozen importlib._bootstrap>", line 1176, in _find_and_load
  File "<frozen importlib._bootstrap>", line 1147, in _find_and_load_unlocked
  File "<frozen importlib._bootstrap>", line 690, in _load_unlocked
  File "<frozen importlib._bootstrap_external>", line 940, in exec_module
  File "<frozen importlib._bootstrap>", line 241, in _call_with_frames_removed
  File "/home/ubuntu/carecove_debug/carecove/urls.py", line 12, in <module>
    path('', include('shop.urls')),
             ^^^^^^^^^^^^^^^^^^^^
  File "/home/ubuntu/.local/lib/python3.11/site-packages/django/urls/conf.py", line 39, in include
    urlconf_module = import_module(urlconf_module)
                     ^^^^^^^^^^^^^^^^^^^^^^^^^^^^^
  File "/opt/computersetup/.pyenv/versions/3.11.6/lib/python3.11/importlib/__init__.py", line 126, in import_module
    return _bootstrap._gcd_import(name[level:], package, level)
           ^^^^^^^^^^^^^^^^^^^^^^^^^^^^^^^^^^^^^^^^^^^^^^^^^^^^
  File "<frozen importlib._bootstrap>", line 1204, in _gcd_import
  File "<frozen importlib._bootstrap>", line 1176, in _find_and_load
  File "<frozen importlib._bootstrap>", line 1147, in _find_and_load_unlocked
  File "<frozen importlib._bootstrap>", line 690, in _load_unlocked
  File "<frozen importlib._bootstrap_external>", line 940, in exec_module
  File "<frozen importlib._bootstrap>", line 241, in _call_with_frames_removed
  File "/home/ubuntu/carecove_debug/shop/urls.py", line 3, in <module>
    from . import views
  File "/home/ubuntu/carecove_debug/shop/views.py", line 7, in <module>
    from .models import Product, Category, ProductReview
  File "/home/ubuntu/carecove_debug/shop/models.py", line 8, in <module>
    class Category(models.Model):
  File "/home/ubuntu/.local/lib/python3.11/site-packages/django/db/models/base.py", line 136, in __new__
    raise RuntimeError(
RuntimeError: Model class shop.models.Category doesn't declare an explicit app_label and isn't in an application in INSTALLED_APPS.
✓ newsletter: INSTALLED_APPS test PASSED
Testing newsletter with URL patterns...
Traceback (most recent call last):
  File "/home/ubuntu/carecove_debug/manage.py", line 22, in <module>
    main()
  File "/home/ubuntu/carecove_debug/manage.py", line 18, in main
    execute_from_command_line(sys.argv)
  File "/home/ubuntu/.local/lib/python3.11/site-packages/django/core/management/__init__.py", line 442, in execute_from_command_line
    utility.execute()
  File "/home/ubuntu/.local/lib/python3.11/site-packages/django/core/management/__init__.py", line 436, in execute
    self.fetch_command(subcommand).run_from_argv(self.argv)
  File "/home/ubuntu/.local/lib/python3.11/site-packages/django/core/management/base.py", line 416, in run_from_argv
    self.execute(*args, **cmd_options)
  File "/home/ubuntu/.local/lib/python3.11/site-packages/django/core/management/base.py", line 460, in execute
    output = self.handle(*args, **options)
             ^^^^^^^^^^^^^^^^^^^^^^^^^^^^^
  File "/home/ubuntu/.local/lib/python3.11/site-packages/django/core/management/commands/check.py", line 81, in handle
    self.check(
  File "/home/ubuntu/.local/lib/python3.11/site-packages/django/core/management/base.py", line 492, in check
    all_issues = checks.run_checks(
                 ^^^^^^^^^^^^^^^^^^
  File "/home/ubuntu/.local/lib/python3.11/site-packages/django/core/checks/registry.py", line 89, in run_checks
    new_errors = check(app_configs=app_configs, databases=databases)
                 ^^^^^^^^^^^^^^^^^^^^^^^^^^^^^^^^^^^^^^^^^^^^^^^^^^^
  File "/home/ubuntu/.local/lib/python3.11/site-packages/django/core/checks/urls.py", line 44, in check_url_namespaces_unique
    all_namespaces = _load_all_namespaces(resolver)
                     ^^^^^^^^^^^^^^^^^^^^^^^^^^^^^^
  File "/home/ubuntu/.local/lib/python3.11/site-packages/django/core/checks/urls.py", line 63, in _load_all_namespaces
    url_patterns = getattr(resolver, "url_patterns", [])
                   ^^^^^^^^^^^^^^^^^^^^^^^^^^^^^^^^^^^^^
  File "/home/ubuntu/.local/lib/python3.11/site-packages/django/utils/functional.py", line 47, in __get__
    res = instance.__dict__[self.name] = self.func(instance)
                                         ^^^^^^^^^^^^^^^^^^^
  File "/home/ubuntu/.local/lib/python3.11/site-packages/django/urls/resolvers.py", line 718, in url_patterns
    patterns = getattr(self.urlconf_module, "urlpatterns", self.urlconf_module)
                       ^^^^^^^^^^^^^^^^^^^
  File "/home/ubuntu/.local/lib/python3.11/site-packages/django/utils/functional.py", line 47, in __get__
    res = instance.__dict__[self.name] = self.func(instance)
                                         ^^^^^^^^^^^^^^^^^^^
  File "/home/ubuntu/.local/lib/python3.11/site-packages/django/urls/resolvers.py", line 711, in urlconf_module
    return import_module(self.urlconf_name)
           ^^^^^^^^^^^^^^^^^^^^^^^^^^^^^^^^
  File "/opt/computersetup/.pyenv/versions/3.11.6/lib/python3.11/importlib/__init__.py", line 126, in import_module
    return _bootstrap._gcd_import(name[level:], package, level)
           ^^^^^^^^^^^^^^^^^^^^^^^^^^^^^^^^^^^^^^^^^^^^^^^^^^^^
  File "<frozen importlib._bootstrap>", line 1204, in _gcd_import
  File "<frozen importlib._bootstrap>", line 1176, in _find_and_load
  File "<frozen importlib._bootstrap>", line 1147, in _find_and_load_unlocked
  File "<frozen importlib._bootstrap>", line 690, in _load_unlocked
  File "<frozen importlib._bootstrap_external>", line 940, in exec_module
  File "<frozen importlib._bootstrap>", line 241, in _call_with_frames_removed
  File "/home/ubuntu/carecove_debug/carecove/urls.py", line 12, in <module>
    path('', include('shop.urls')),
             ^^^^^^^^^^^^^^^^^^^^
  File "/home/ubuntu/.local/lib/python3.11/site-packages/django/urls/conf.py", line 39, in include
    urlconf_module = import_module(urlconf_module)
                     ^^^^^^^^^^^^^^^^^^^^^^^^^^^^^
  File "/opt/computersetup/.pyenv/versions/3.11.6/lib/python3.11/importlib/__init__.py", line 126, in import_module
    return _bootstrap._gcd_import(name[level:], package, level)
           ^^^^^^^^^^^^^^^^^^^^^^^^^^^^^^^^^^^^^^^^^^^^^^^^^^^^
  File "<frozen importlib._bootstrap>", line 1204, in _gcd_import
  File "<frozen importlib._bootstrap>", line 1176, in _find_and_load
  File "<frozen importlib._bootstrap>", line 1147, in _find_and_load_unlocked
  File "<frozen importlib._bootstrap>", line 690, in _load_unlocked
  File "<frozen importlib._bootstrap_external>", line 940, in exec_module
  File "<frozen importlib._bootstrap>", line 241, in _call_with_frames_removed
  File "/home/ubuntu/carecove_debug/shop/urls.py", line 3, in <module>
    from . import views
  File "/home/ubuntu/carecove_debug/shop/views.py", line 7, in <module>
    from .models import Product, Category, ProductReview
  File "/home/ubuntu/carecove_debug/shop/models.py", line 8, in <module>
    class Category(models.Model):
  File "/home/ubuntu/.local/lib/python3.11/site-packages/django/db/models/base.py", line 136, in __new__
    raise RuntimeError(
RuntimeError: Model class shop.models.Category doesn't declare an explicit app_label and isn't in an application in INSTALLED_APPS.
✓ newsletter: URL patterns test PASSED

=== Testing app: chatbot ===
Testing chatbot in INSTALLED_APPS only...
Traceback (most recent call last):
  File "/home/ubuntu/carecove_debug/manage.py", line 22, in <module>
    main()
  File "/home/ubuntu/carecove_debug/manage.py", line 18, in main
    execute_from_command_line(sys.argv)
  File "/home/ubuntu/.local/lib/python3.11/site-packages/django/core/management/__init__.py", line 442, in execute_from_command_line
    utility.execute()
  File "/home/ubuntu/.local/lib/python3.11/site-packages/django/core/management/__init__.py", line 436, in execute
    self.fetch_command(subcommand).run_from_argv(self.argv)
  File "/home/ubuntu/.local/lib/python3.11/site-packages/django/core/management/base.py", line 416, in run_from_argv
    self.execute(*args, **cmd_options)
  File "/home/ubuntu/.local/lib/python3.11/site-packages/django/core/management/base.py", line 460, in execute
    output = self.handle(*args, **options)
             ^^^^^^^^^^^^^^^^^^^^^^^^^^^^^
  File "/home/ubuntu/.local/lib/python3.11/site-packages/django/core/management/commands/check.py", line 81, in handle
    self.check(
  File "/home/ubuntu/.local/lib/python3.11/site-packages/django/core/management/base.py", line 492, in check
    all_issues = checks.run_checks(
                 ^^^^^^^^^^^^^^^^^^
  File "/home/ubuntu/.local/lib/python3.11/site-packages/django/core/checks/registry.py", line 89, in run_checks
    new_errors = check(app_configs=app_configs, databases=databases)
                 ^^^^^^^^^^^^^^^^^^^^^^^^^^^^^^^^^^^^^^^^^^^^^^^^^^^
  File "/home/ubuntu/.local/lib/python3.11/site-packages/django/core/checks/urls.py", line 44, in check_url_namespaces_unique
    all_namespaces = _load_all_namespaces(resolver)
                     ^^^^^^^^^^^^^^^^^^^^^^^^^^^^^^
  File "/home/ubuntu/.local/lib/python3.11/site-packages/django/core/checks/urls.py", line 63, in _load_all_namespaces
    url_patterns = getattr(resolver, "url_patterns", [])
                   ^^^^^^^^^^^^^^^^^^^^^^^^^^^^^^^^^^^^^
  File "/home/ubuntu/.local/lib/python3.11/site-packages/django/utils/functional.py", line 47, in __get__
    res = instance.__dict__[self.name] = self.func(instance)
                                         ^^^^^^^^^^^^^^^^^^^
  File "/home/ubuntu/.local/lib/python3.11/site-packages/django/urls/resolvers.py", line 718, in url_patterns
    patterns = getattr(self.urlconf_module, "urlpatterns", self.urlconf_module)
                       ^^^^^^^^^^^^^^^^^^^
  File "/home/ubuntu/.local/lib/python3.11/site-packages/django/utils/functional.py", line 47, in __get__
    res = instance.__dict__[self.name] = self.func(instance)
                                         ^^^^^^^^^^^^^^^^^^^
  File "/home/ubuntu/.local/lib/python3.11/site-packages/django/urls/resolvers.py", line 711, in urlconf_module
    return import_module(self.urlconf_name)
           ^^^^^^^^^^^^^^^^^^^^^^^^^^^^^^^^
  File "/opt/computersetup/.pyenv/versions/3.11.6/lib/python3.11/importlib/__init__.py", line 126, in import_module
    return _bootstrap._gcd_import(name[level:], package, level)
           ^^^^^^^^^^^^^^^^^^^^^^^^^^^^^^^^^^^^^^^^^^^^^^^^^^^^
  File "<frozen importlib._bootstrap>", line 1204, in _gcd_import
  File "<frozen importlib._bootstrap>", line 1176, in _find_and_load
  File "<frozen importlib._bootstrap>", line 1147, in _find_and_load_unlocked
  File "<frozen importlib._bootstrap>", line 690, in _load_unlocked
  File "<frozen importlib._bootstrap_external>", line 940, in exec_module
  File "<frozen importlib._bootstrap>", line 241, in _call_with_frames_removed
  File "/home/ubuntu/carecove_debug/carecove/urls.py", line 12, in <module>
    path('', include('shop.urls')),
             ^^^^^^^^^^^^^^^^^^^^
  File "/home/ubuntu/.local/lib/python3.11/site-packages/django/urls/conf.py", line 39, in include
    urlconf_module = import_module(urlconf_module)
                     ^^^^^^^^^^^^^^^^^^^^^^^^^^^^^
  File "/opt/computersetup/.pyenv/versions/3.11.6/lib/python3.11/importlib/__init__.py", line 126, in import_module
    return _bootstrap._gcd_import(name[level:], package, level)
           ^^^^^^^^^^^^^^^^^^^^^^^^^^^^^^^^^^^^^^^^^^^^^^^^^^^^
  File "<frozen importlib._bootstrap>", line 1204, in _gcd_import
  File "<frozen importlib._bootstrap>", line 1176, in _find_and_load
  File "<frozen importlib._bootstrap>", line 1147, in _find_and_load_unlocked
  File "<frozen importlib._bootstrap>", line 690, in _load_unlocked
  File "<frozen importlib._bootstrap_external>", line 940, in exec_module
  File "<frozen importlib._bootstrap>", line 241, in _call_with_frames_removed
  File "/home/ubuntu/carecove_debug/shop/urls.py", line 3, in <module>
    from . import views
  File "/home/ubuntu/carecove_debug/shop/views.py", line 7, in <module>
    from .models import Product, Category, ProductReview
  File "/home/ubuntu/carecove_debug/shop/models.py", line 8, in <module>
    class Category(models.Model):
  File "/home/ubuntu/.local/lib/python3.11/site-packages/django/db/models/base.py", line 136, in __new__
    raise RuntimeError(
RuntimeError: Model class shop.models.Category doesn't declare an explicit app_label and isn't in an application in INSTALLED_APPS.
✓ chatbot: INSTALLED_APPS test PASSED
Testing chatbot with URL patterns...
Traceback (most recent call last):
  File "/home/ubuntu/carecove_debug/manage.py", line 22, in <module>
    main()
  File "/home/ubuntu/carecove_debug/manage.py", line 18, in main
    execute_from_command_line(sys.argv)
  File "/home/ubuntu/.local/lib/python3.11/site-packages/django/core/management/__init__.py", line 442, in execute_from_command_line
    utility.execute()
  File "/home/ubuntu/.local/lib/python3.11/site-packages/django/core/management/__init__.py", line 436, in execute
    self.fetch_command(subcommand).run_from_argv(self.argv)
  File "/home/ubuntu/.local/lib/python3.11/site-packages/django/core/management/base.py", line 416, in run_from_argv
    self.execute(*args, **cmd_options)
  File "/home/ubuntu/.local/lib/python3.11/site-packages/django/core/management/base.py", line 460, in execute
    output = self.handle(*args, **options)
             ^^^^^^^^^^^^^^^^^^^^^^^^^^^^^
  File "/home/ubuntu/.local/lib/python3.11/site-packages/django/core/management/commands/check.py", line 81, in handle
    self.check(
  File "/home/ubuntu/.local/lib/python3.11/site-packages/django/core/management/base.py", line 492, in check
    all_issues = checks.run_checks(
                 ^^^^^^^^^^^^^^^^^^
  File "/home/ubuntu/.local/lib/python3.11/site-packages/django/core/checks/registry.py", line 89, in run_checks
    new_errors = check(app_configs=app_configs, databases=databases)
                 ^^^^^^^^^^^^^^^^^^^^^^^^^^^^^^^^^^^^^^^^^^^^^^^^^^^
  File "/home/ubuntu/.local/lib/python3.11/site-packages/django/core/checks/urls.py", line 44, in check_url_namespaces_unique
    all_namespaces = _load_all_namespaces(resolver)
                     ^^^^^^^^^^^^^^^^^^^^^^^^^^^^^^
  File "/home/ubuntu/.local/lib/python3.11/site-packages/django/core/checks/urls.py", line 63, in _load_all_namespaces
    url_patterns = getattr(resolver, "url_patterns", [])
                   ^^^^^^^^^^^^^^^^^^^^^^^^^^^^^^^^^^^^^
  File "/home/ubuntu/.local/lib/python3.11/site-packages/django/utils/functional.py", line 47, in __get__
    res = instance.__dict__[self.name] = self.func(instance)
                                         ^^^^^^^^^^^^^^^^^^^
  File "/home/ubuntu/.local/lib/python3.11/site-packages/django/urls/resolvers.py", line 718, in url_patterns
    patterns = getattr(self.urlconf_module, "urlpatterns", self.urlconf_module)
                       ^^^^^^^^^^^^^^^^^^^
  File "/home/ubuntu/.local/lib/python3.11/site-packages/django/utils/functional.py", line 47, in __get__
    res = instance.__dict__[self.name] = self.func(instance)
                                         ^^^^^^^^^^^^^^^^^^^
  File "/home/ubuntu/.local/lib/python3.11/site-packages/django/urls/resolvers.py", line 711, in urlconf_module
    return import_module(self.urlconf_name)
           ^^^^^^^^^^^^^^^^^^^^^^^^^^^^^^^^
  File "/opt/computersetup/.pyenv/versions/3.11.6/lib/python3.11/importlib/__init__.py", line 126, in import_module
    return _bootstrap._gcd_import(name[level:], package, level)
           ^^^^^^^^^^^^^^^^^^^^^^^^^^^^^^^^^^^^^^^^^^^^^^^^^^^^
  File "<frozen importlib._bootstrap>", line 1204, in _gcd_import
  File "<frozen importlib._bootstrap>", line 1176, in _find_and_load
  File "<frozen importlib._bootstrap>", line 1147, in _find_and_load_unlocked
  File "<frozen importlib._bootstrap>", line 690, in _load_unlocked
  File "<frozen importlib._bootstrap_external>", line 940, in exec_module
  File "<frozen importlib._bootstrap>", line 241, in _call_with_frames_removed
  File "/home/ubuntu/carecove_debug/carecove/urls.py", line 12, in <module>
    path('', include('shop.urls')),
             ^^^^^^^^^^^^^^^^^^^^
  File "/home/ubuntu/.local/lib/python3.11/site-packages/django/urls/conf.py", line 39, in include
    urlconf_module = import_module(urlconf_module)
                     ^^^^^^^^^^^^^^^^^^^^^^^^^^^^^
  File "/opt/computersetup/.pyenv/versions/3.11.6/lib/python3.11/importlib/__init__.py", line 126, in import_module
    return _bootstrap._gcd_import(name[level:], package, level)
           ^^^^^^^^^^^^^^^^^^^^^^^^^^^^^^^^^^^^^^^^^^^^^^^^^^^^
  File "<frozen importlib._bootstrap>", line 1204, in _gcd_import
  File "<frozen importlib._bootstrap>", line 1176, in _find_and_load
  File "<frozen importlib._bootstrap>", line 1147, in _find_and_load_unlocked
  File "<frozen importlib._bootstrap>", line 690, in _load_unlocked
  File "<frozen importlib._bootstrap_external>", line 940, in exec_module
  File "<frozen importlib._bootstrap>", line 241, in _call_with_frames_removed
  File "/home/ubuntu/carecove_debug/shop/urls.py", line 3, in <module>
    from . import views
  File "/home/ubuntu/carecove_debug/shop/views.py", line 7, in <module>
    from .models import Product, Category, ProductReview
  File "/home/ubuntu/carecove_debug/shop/models.py", line 8, in <module>
    class Category(models.Model):
  File "/home/ubuntu/.local/lib/python3.11/site-packages/django/db/models/base.py", line 136, in __new__
    raise RuntimeError(
RuntimeError: Model class shop.models.Category doesn't declare an explicit app_label and isn't in an application in INSTALLED_APPS.
✓ chatbot: URL patterns test PASSED

=== Testing app: admin_panel ===
Testing admin_panel in INSTALLED_APPS only...
Traceback (most recent call last):
  File "/home/ubuntu/carecove_debug/manage.py", line 22, in <module>
    main()
  File "/home/ubuntu/carecove_debug/manage.py", line 18, in main
    execute_from_command_line(sys.argv)
  File "/home/ubuntu/.local/lib/python3.11/site-packages/django/core/management/__init__.py", line 442, in execute_from_command_line
    utility.execute()
  File "/home/ubuntu/.local/lib/python3.11/site-packages/django/core/management/__init__.py", line 436, in execute
    self.fetch_command(subcommand).run_from_argv(self.argv)
  File "/home/ubuntu/.local/lib/python3.11/site-packages/django/core/management/base.py", line 416, in run_from_argv
    self.execute(*args, **cmd_options)
  File "/home/ubuntu/.local/lib/python3.11/site-packages/django/core/management/base.py", line 460, in execute
    output = self.handle(*args, **options)
             ^^^^^^^^^^^^^^^^^^^^^^^^^^^^^
  File "/home/ubuntu/.local/lib/python3.11/site-packages/django/core/management/commands/check.py", line 81, in handle
    self.check(
  File "/home/ubuntu/.local/lib/python3.11/site-packages/django/core/management/base.py", line 492, in check
    all_issues = checks.run_checks(
                 ^^^^^^^^^^^^^^^^^^
  File "/home/ubuntu/.local/lib/python3.11/site-packages/django/core/checks/registry.py", line 89, in run_checks
    new_errors = check(app_configs=app_configs, databases=databases)
                 ^^^^^^^^^^^^^^^^^^^^^^^^^^^^^^^^^^^^^^^^^^^^^^^^^^^
  File "/home/ubuntu/.local/lib/python3.11/site-packages/django/core/checks/urls.py", line 44, in check_url_namespaces_unique
    all_namespaces = _load_all_namespaces(resolver)
                     ^^^^^^^^^^^^^^^^^^^^^^^^^^^^^^
  File "/home/ubuntu/.local/lib/python3.11/site-packages/django/core/checks/urls.py", line 63, in _load_all_namespaces
    url_patterns = getattr(resolver, "url_patterns", [])
                   ^^^^^^^^^^^^^^^^^^^^^^^^^^^^^^^^^^^^^
  File "/home/ubuntu/.local/lib/python3.11/site-packages/django/utils/functional.py", line 47, in __get__
    res = instance.__dict__[self.name] = self.func(instance)
                                         ^^^^^^^^^^^^^^^^^^^
  File "/home/ubuntu/.local/lib/python3.11/site-packages/django/urls/resolvers.py", line 718, in url_patterns
    patterns = getattr(self.urlconf_module, "urlpatterns", self.urlconf_module)
                       ^^^^^^^^^^^^^^^^^^^
  File "/home/ubuntu/.local/lib/python3.11/site-packages/django/utils/functional.py", line 47, in __get__
    res = instance.__dict__[self.name] = self.func(instance)
                                         ^^^^^^^^^^^^^^^^^^^
  File "/home/ubuntu/.local/lib/python3.11/site-packages/django/urls/resolvers.py", line 711, in urlconf_module
    return import_module(self.urlconf_name)
           ^^^^^^^^^^^^^^^^^^^^^^^^^^^^^^^^
  File "/opt/computersetup/.pyenv/versions/3.11.6/lib/python3.11/importlib/__init__.py", line 126, in import_module
    return _bootstrap._gcd_import(name[level:], package, level)
           ^^^^^^^^^^^^^^^^^^^^^^^^^^^^^^^^^^^^^^^^^^^^^^^^^^^^
  File "<frozen importlib._bootstrap>", line 1204, in _gcd_import
  File "<frozen importlib._bootstrap>", line 1176, in _find_and_load
  File "<frozen importlib._bootstrap>", line 1147, in _find_and_load_unlocked
  File "<frozen importlib._bootstrap>", line 690, in _load_unlocked
  File "<frozen importlib._bootstrap_external>", line 940, in exec_module
  File "<frozen importlib._bootstrap>", line 241, in _call_with_frames_removed
  File "/home/ubuntu/carecove_debug/carecove/urls.py", line 12, in <module>
    path('', include('shop.urls')),
             ^^^^^^^^^^^^^^^^^^^^
  File "/home/ubuntu/.local/lib/python3.11/site-packages/django/urls/conf.py", line 39, in include
    urlconf_module = import_module(urlconf_module)
                     ^^^^^^^^^^^^^^^^^^^^^^^^^^^^^
  File "/opt/computersetup/.pyenv/versions/3.11.6/lib/python3.11/importlib/__init__.py", line 126, in import_module
    return _bootstrap._gcd_import(name[level:], package, level)
           ^^^^^^^^^^^^^^^^^^^^^^^^^^^^^^^^^^^^^^^^^^^^^^^^^^^^
  File "<frozen importlib._bootstrap>", line 1204, in _gcd_import
  File "<frozen importlib._bootstrap>", line 1176, in _find_and_load
  File "<frozen importlib._bootstrap>", line 1147, in _find_and_load_unlocked
  File "<frozen importlib._bootstrap>", line 690, in _load_unlocked
  File "<frozen importlib._bootstrap_external>", line 940, in exec_module
  File "<frozen importlib._bootstrap>", line 241, in _call_with_frames_removed
  File "/home/ubuntu/carecove_debug/shop/urls.py", line 3, in <module>
    from . import views
  File "/home/ubuntu/carecove_debug/shop/views.py", line 7, in <module>
    from .models import Product, Category, ProductReview
  File "/home/ubuntu/carecove_debug/shop/models.py", line 8, in <module>
    class Category(models.Model):
  File "/home/ubuntu/.local/lib/python3.11/site-packages/django/db/models/base.py", line 136, in __new__
    raise RuntimeError(
RuntimeError: Model class shop.models.Category doesn't declare an explicit app_label and isn't in an application in INSTALLED_APPS.
✓ admin_panel: INSTALLED_APPS test PASSED
Testing admin_panel with URL patterns...
Traceback (most recent call last):
  File "/home/ubuntu/carecove_debug/manage.py", line 22, in <module>
    main()
  File "/home/ubuntu/carecove_debug/manage.py", line 18, in main
    execute_from_command_line(sys.argv)
  File "/home/ubuntu/.local/lib/python3.11/site-packages/django/core/management/__init__.py", line 442, in execute_from_command_line
    utility.execute()
  File "/home/ubuntu/.local/lib/python3.11/site-packages/django/core/management/__init__.py", line 436, in execute
    self.fetch_command(subcommand).run_from_argv(self.argv)
  File "/home/ubuntu/.local/lib/python3.11/site-packages/django/core/management/base.py", line 416, in run_from_argv
    self.execute(*args, **cmd_options)
  File "/home/ubuntu/.local/lib/python3.11/site-packages/django/core/management/base.py", line 460, in execute
    output = self.handle(*args, **options)
             ^^^^^^^^^^^^^^^^^^^^^^^^^^^^^
  File "/home/ubuntu/.local/lib/python3.11/site-packages/django/core/management/commands/check.py", line 81, in handle
    self.check(
  File "/home/ubuntu/.local/lib/python3.11/site-packages/django/core/management/base.py", line 492, in check
    all_issues = checks.run_checks(
                 ^^^^^^^^^^^^^^^^^^
  File "/home/ubuntu/.local/lib/python3.11/site-packages/django/core/checks/registry.py", line 89, in run_checks
    new_errors = check(app_configs=app_configs, databases=databases)
                 ^^^^^^^^^^^^^^^^^^^^^^^^^^^^^^^^^^^^^^^^^^^^^^^^^^^
  File "/home/ubuntu/.local/lib/python3.11/site-packages/django/core/checks/urls.py", line 44, in check_url_namespaces_unique
    all_namespaces = _load_all_namespaces(resolver)
                     ^^^^^^^^^^^^^^^^^^^^^^^^^^^^^^
  File "/home/ubuntu/.local/lib/python3.11/site-packages/django/core/checks/urls.py", line 63, in _load_all_namespaces
    url_patterns = getattr(resolver, "url_patterns", [])
                   ^^^^^^^^^^^^^^^^^^^^^^^^^^^^^^^^^^^^^
  File "/home/ubuntu/.local/lib/python3.11/site-packages/django/utils/functional.py", line 47, in __get__
    res = instance.__dict__[self.name] = self.func(instance)
                                         ^^^^^^^^^^^^^^^^^^^
  File "/home/ubuntu/.local/lib/python3.11/site-packages/django/urls/resolvers.py", line 718, in url_patterns
    patterns = getattr(self.urlconf_module, "urlpatterns", self.urlconf_module)
                       ^^^^^^^^^^^^^^^^^^^
  File "/home/ubuntu/.local/lib/python3.11/site-packages/django/utils/functional.py", line 47, in __get__
    res = instance.__dict__[self.name] = self.func(instance)
                                         ^^^^^^^^^^^^^^^^^^^
  File "/home/ubuntu/.local/lib/python3.11/site-packages/django/urls/resolvers.py", line 711, in urlconf_module
    return import_module(self.urlconf_name)
           ^^^^^^^^^^^^^^^^^^^^^^^^^^^^^^^^
  File "/opt/computersetup/.pyenv/versions/3.11.6/lib/python3.11/importlib/__init__.py", line 126, in import_module
    return _bootstrap._gcd_import(name[level:], package, level)
           ^^^^^^^^^^^^^^^^^^^^^^^^^^^^^^^^^^^^^^^^^^^^^^^^^^^^
  File "<frozen importlib._bootstrap>", line 1204, in _gcd_import
  File "<frozen importlib._bootstrap>", line 1176, in _find_and_load
  File "<frozen importlib._bootstrap>", line 1147, in _find_and_load_unlocked
  File "<frozen importlib._bootstrap>", line 690, in _load_unlocked
  File "<frozen importlib._bootstrap_external>", line 940, in exec_module
  File "<frozen importlib._bootstrap>", line 241, in _call_with_frames_removed
  File "/home/ubuntu/carecove_debug/carecove/urls.py", line 11, in <module>
    path('admin-panel/', include('admin_panel.urls')),
                         ^^^^^^^^^^^^^^^^^^^^^^^^^^^
  File "/home/ubuntu/.local/lib/python3.11/site-packages/django/urls/conf.py", line 39, in include
    urlconf_module = import_module(urlconf_module)
                     ^^^^^^^^^^^^^^^^^^^^^^^^^^^^^
  File "/opt/computersetup/.pyenv/versions/3.11.6/lib/python3.11/importlib/__init__.py", line 126, in import_module
    return _bootstrap._gcd_import(name[level:], package, level)
           ^^^^^^^^^^^^^^^^^^^^^^^^^^^^^^^^^^^^^^^^^^^^^^^^^^^^
  File "<frozen importlib._bootstrap>", line 1204, in _gcd_import
  File "<frozen importlib._bootstrap>", line 1176, in _find_and_load
  File "<frozen importlib._bootstrap>", line 1147, in _find_and_load_unlocked
  File "<frozen importlib._bootstrap>", line 690, in _load_unlocked
  File "<frozen importlib._bootstrap_external>", line 940, in exec_module
  File "<frozen importlib._bootstrap>", line 241, in _call_with_frames_removed
  File "/home/ubuntu/carecove_debug/admin_panel/urls.py", line 2, in <module>
    from . import views
  File "/home/ubuntu/carecove_debug/admin_panel/views.py", line 24, in <module>
    from shop.models import Product, Category, ProductReview
  File "/home/ubuntu/carecove_debug/shop/models.py", line 8, in <module>
    class Category(models.Model):
  File "/home/ubuntu/.local/lib/python3.11/site-packages/django/db/models/base.py", line 136, in __new__
    raise RuntimeError(
RuntimeError: Model class shop.models.Category doesn't declare an explicit app_label and isn't in an application in INSTALLED_APPS.
✓ admin_panel: URL patterns test PASSED

=== Debugging Complete ===
Check debug_report_v2.txt for detailed results
